Workbook

Sheet Especialista
B2: Percentual de Sucessos - Robô CC
B3: PR | C3: PBA | D3: PG | E3: PRA | F3: PRB | G3: PRD
B4: =100/116 -> 0.86206897 | C4: =100/116 -> 0.86206897 | D4: =100/350 -> 0.28571429 | E4: =100/183 -> 0.54644809 | F4: =100/169 -> 0.59171598 | G4: =100/118 -> 0.84745763
B7: Percentual de Sucessos - Robô Especialista
B8: PR | C8: PBA | D8: PG | E8: PRA | F8: PRB | G8: PRD
B9: =100/203 -> 0.49261084 | C9: =100/472 -> 0.21186441 | D9: =100/129 -> 0.7751938 | E9: =100/1570 -> 0.063694268 | F9: =100/132 -> 0.75757576 | G9: =100/114 -> 0.87719298
C11: Média Robos especialistas | M11: Média Robo Generalista
C12: Tempo no sucesso | E12: Velocidade no sucesso | G12: Distância | I12: Velocidade | K12: Sucesso | M12: Tempo no sucesso | O12: Velocidade no sucesso | Q12: Distância | S12: Velocidade | U12: Sucesso
B13: =Suc_Esp_Tempo!B107 -> PR | C13: 11.408 | D13: 4.5 | E13: 0.792 | F13: 4 | G13: 7.655 | H13: 4 | I13: 0.762 | J13: 4 | K13: 0.4926 | L13: 4 | M13: =Suc_CC_Tempo!C107 -> 11.5672 | N13: 3.5 | O13: =Suc_CC_Velocidade!C107 -> 0.7812 | P13: 3.5 | Q13: ='Tds_CC_Distância'!C107 -> 8.5574 | R13: 2 | S13: =Tds_CC_Velocidade!C107 -> 0.7712 | T13: 3 | U13: =B4 -> 0.86206897 | V13: 1.5
B14: =Suc_Esp_Tempo!B108 -> PBA | C14: 11.213 | D14: 4.5 | E14: 0.811 | F14: 5 | G14: 5.499 | H14: 5 | I14: 0.608 | J14: 5 | K14: 0.2119 | L14: 5 | M14: =Suc_CC_Tempo!C108 -> 11.6628 | N14: 3.5 | O14: =Suc_CC_Velocidade!C108 -> 0.7743 | P14: 3.5 | Q14: ='Tds_CC_Distância'!C108 -> 8.4592 | R14: 2 | S14: =Tds_CC_Velocidade!C108 -> 0.7561 | T14: 3 | U14: =C4 -> 0.86206897 | V14: 1.5
B15: =Suc_Esp_Tempo!B109 -> PG | C15: 9.794 | D15: 1.5 | E15: 0.924 | F15: 1.5 | G15: 8.552 | H15: 2 | I15: 0.882 | J15: 2.5 | K15: 0.7752 | L15: 2 | M15: =Suc_CC_Tempo!C109 -> 10.8223 | N15: 2 | O15: =Suc_CC_Velocidade!C109 -> 0.8348 | P15: 2 | Q15: ='Tds_CC_Distância'!C109 -> 7.1524 | R15: 6 | S15: =Tds_CC_Velocidade!C109 -> 0.7754 | T15: 3 | U15: =D4 -> 0.28571429 | V15: 6
B16: =Suc_Esp_Tempo!B110 -> PRA | C16: 16.93 | D16: 6 | E16: 0.545 | F16: 6 | G16: 3.769 | H16: 6 | I16: 0.298 | J16: 6 | K16: 0.0637 | L16: 6 | M16: =Suc_CC_Tempo!C110 -> 16.0655 | N16: 6 | O16: =Suc_CC_Velocidade!C110 -> 0.5635 | P16: 6 | Q16: ='Tds_CC_Distância'!C110 -> 7.5673 | R16: 4.5 | S16: =Tds_CC_Velocidade!C110 -> 0.5295 | T16: 6 | U16: =E4 -> 0.54644809 | V16: 5
B17: =Suc_Esp_Tempo!B111 -> PRB | C17: 10.234 | D17: 3 | E17: 0.883 | F17: 3 | G17: 8.511 | H17: 2 | I17: 0.86 | J17: 2.5 | K17: 0.7576 | L17: 3 | M17: =Suc_CC_Tempo!C111 -> 11.9652 | N17: 5 | O17: =Suc_CC_Velocidade!C111 -> 0.7566 | P17: 5 | Q17: ='Tds_CC_Distância'!C111 -> 7.5736 | R17: 4.5 | S17: =Tds_CC_Velocidade!C111 -> 0.7268 | T17: 5 | U17: =F4 -> 0.59171598 | V17: 4
B18: =Suc_Esp_Tempo!B112 -> PRD | C18: 9.706 | D18: 1.5 | E18: 0.931 | F18: 1.5 | G18: 8.753 | H18: 2 | I18: 0.922 | J18: 1 | K18: 0.8772 | L18: 1 | M18: =Suc_CC_Tempo!C112 -> 10.2297 | N18: 1 | O18: =Suc_CC_Velocidade!C112 -> 0.8834 | P18: 1 | Q18: ='Tds_CC_Distância'!C112 -> 8.5144 | R18: 2 | S18: =Tds_CC_Velocidade!C112 -> 0.8726 | T18: 1 | U18: =G4 -> 0.84745763 | V18: 3
B21: PRA | C21: 57.5
B22: PBA | C22: 38
B23: PRB | C23: 37
B24: PR | C24: 34
B25: PG | C25: 28.5
B26: PRD | C26: 15

Sheet Suc_Esp_Tempo
B1: Tempo dos Episódios / Completos de 9 m - Robô Especialista
B2: PR | C2: PBA | D2: PG | E2: PRA | F2: PRB | G2: PRD
B3: 11.4 | C3: 12.47 | D3: 10.03 | E3: 14.97 | F3: 10.4 | G3: 9.67
B4: 11.4 | C4: 10.8 | D4: 10.27 | E4: 17.33 | F4: 10.6 | G4: 9.77
B5: 11.83 | C5: 10.27 | D5: 10.43 | E5: 18.57 | F5: 9.63 | G5: 10.13
B6: 11.43 | C6: 12.23 | D6: 9.33 | E6: 19.93 | F6: 9.87 | G6: 9.8
B7: 11.57 | C7: 10.43 | D7: 9.37 | E7: 13.8 | F7: 10.27 | G7: 10.23
B8: 10.5 | C8: 11.47 | D8: 9.93 | E8: 15.9 | F8: 11.03 | G8: 10.17
B9: 11.17 | C9: 10.57 | D9: 9.23 | E9: 17.07 | F9: 10.8 | G9: 9.2
B10: 11.77 | C10: 9.77 | D10: 10.3 | E10: 24.6 | F10: 9.93 | G10: 9.8
B11: 11.4 | C11: 11.13 | D11: 9.77 | E11: 18.43 | F11: 9.8 | G11: 8.77
B12: 11 | C12: 9.93 | D12: 9.23 | E12: 19.6 | F12: 10.17 | G12: 9.17
B13: 11.33 | C13: 10.53 | D13: 9.7 | E13: 13.87 | F13: 9.83 | G13: 10.03
B14: 10.73 | C14: 10.93 | D14: 9.6 | E14: 15.47 | F14: 11.73 | G14: 9.9
... B102: 12.47 | C102: 11.17 | D102: 10.27 | E102: 14.23 | F102: 10.43 | G102: 9.7
B105: 1. ESTATÍSTICAS DESCRITIVAS
B106: Variável | C106: Média | D106: DP | E106: Mediana | F106: IC 95% Inferior | G106: IC 95% Superior | H106: Mínimo | I106: Máximo | J106: CV (%)
B107: PR | C107: 11.408 | D107: 0.4886 | E107: 11.4 | F107: 11.3122 | G107: 11.5038 | H107: 10.23 | I107: 13.03 | J107: 4.3
B108: PBA | C108: 11.2125 | D108: 1.012 | E108: 11.1 | F108: 11.0141 | G108: 11.4109 | H108: 9.63 | I108: 14.4 | J108: 9
B109: PG | C109: 9.7941 | D109: 0.5382 | E109: 9.685 | F109: 9.6886 | G109: 9.8996 | H109: 8.77 | I109: 11.8 | J109: 5.5
B110: PRA | C110: 16.9297 | D110: 2.6317 | E110: 16.47 | F110: 16.4139 | G110: 17.4455 | H110: 12.53 | I110: 24.6 | J110: 15.5
B111: PRB | C111: 10.2341 | D111: 0.4357 | E111: 10.17 | F111: 10.1487 | G111: 10.3195 | H111: 9.43 | I111: 11.73 | J111: 4.3
B112: PRD | C112: 9.7063 | D112: 0.4062 | E112: 9.715 | F112: 9.6267 | G112: 9.7859 | H112: 8.77 | I112: 10.93 | J112: 4.2
B115: 2. TESTE DE LEVENE
B116: Estatística F | C116: p-valor | D116: Resultado
B117: 74.9322 | C117: < 0,001 | D117: Não Homogêneas
B120: 3. ANOVA DE WELCH
B121: F | C121: gl entre | D121: gl dentro | E121: p-valor | F121: Resultado
B122: 303.2664 | C122: 5 | D122: 8 | E122: < 0,001 | F122: Significativa
B125: 4. TESTE POST-HOC - Games-Howell
B126: Grupo 1 | C126: Grupo 2 | D126: Diferença | E126: Erro Padrão | F126: IC 95% Inferior | G126: IC 95% Superior | H126: p-valor | I126: Significativo
B127: PR | C127: PBA | D127: 0.1955 | E127: 0.1124 | F127: -0.0267 | G127: 0.4177 | H127: 0.0841 | I127: NÃO
B128: PR | C128: PG | D128: 1.6139 | E128: 0.0727 | F128: 1.4705 | G128: 1.7573 | H128: < 0,001 | I128: SIM
B129: PR | C129: PRA | D129: -5.5217 | E129: 0.2677 | F129: -6.0524 | G129: -4.991 | H129: < 0,001 | I129: SIM
B130: PR | C130: PRB | D130: 1.1739 | E130: 0.0655 | F130: 1.0448 | G130: 1.303 | H130: < 0,001 | I130: SIM
B131: PR | C131: PRD | D131: 1.7017 | E131: 0.0635 | F131: 1.5764 | G131: 1.827 | H131: < 0,001 | I131: SIM
B132: PBA | C132: PG | D132: 1.4184 | E132: 0.1146 | F132: 1.1919 | G132: 1.6449 | H132: < 0,001 | I132: SIM
B133: PBA | C133: PRA | D133: -5.7172 | E133: 0.282 | F133: -6.2751 | G133: -5.1593 | H133: < 0,001 | I133: SIM
B134: PBA | C134: PRB | D134: 0.9784 | E134: 0.1102 | F134: 0.7605 | G134: 1.1963 | H134: < 0,001 | I134: SIM
B135: PBA | C135: PRD | D135: 1.5062 | E135: 0.1091 | F135: 1.2905 | G135: 1.7219 | H135: < 0,001 | I135: SIM
...

Sheet Suc_Esp_Velocidade
B1: Velocidade Média / Completos 9 m - Robô Especialista
B2: PR | C2: PBA | D2: PG | E2: PRA | F2: PRB | G2: PRD
B3: 0.79 | C3: 0.72 | D3: 0.9 | E3: 0.6 | F3: 0.87 | G3: 0.93
B4: 0.79 | C4: 0.83 | D4: 0.88 | E4: 0.52 | F4: 0.85 | G4: 0.92
B5: 0.76 | C5: 0.88 | D5: 0.86 | E5: 0.49 | F5: 0.94 | G5: 0.89
B6: 0.79 | C6: 0.74 | D6: 0.96 | E6: 0.45 | F6: 0.91 | G6: 0.92
B7: 0.78 | C7: 0.86 | D7: 0.96 | E7: 0.65 | F7: 0.88 | G7: 0.88
B8: 0.86 | C8: 0.79 | D8: 0.91 | E8: 0.57 | F8: 0.82 | G8: 0.89
B9: 0.81 | C9: 0.85 | D9: 0.98 | E9: 0.53 | F9: 0.84 | G9: 0.98
B10: 0.77 | C10: 0.92 | D10: 0.87 | E10: 0.37 | F10: 0.91 | G10: 0.92
B11: 0.79 | C11: 0.81 | D11: 0.92 | E11: 0.49 | F11: 0.92 | G11: 1.03
B12: 0.82 | C12: 0.91 | D12: 0.98 | E12: 0.46 | F12: 0.89 | G12: 0.98
B13: 0.8 | C13: 0.86 | D13: 0.93 | E13: 0.65 | F13: 0.92 | G13: 0.9
B14: 0.84 | C14: 0.82 | D14: 0.94 | E14: 0.58 | F14: 0.77 | G14: 0.91
... B102: 0.72 | C102: 0.81 | D102: 0.88 | E102: 0.63 | F102: 0.86 | G102: 0.93
B105: 1. ESTATÍSTICAS DESCRITIVAS
B106: Variável | C106: Média | D106: DP | E106: Mediana | F106: IC 95% Inferior | G106: IC 95% Superior | H106: Mínimo | I106: Máximo | J106: CV (%)
B107: PR | C107: 0.7917 | D107: 0.0342 | E107: 0.79 | F107: 0.785 | G107: 0.7984 | H107: 0.69 | I107: 0.88 | J107: 4.3
B108: PBA | C108: 0.8108 | D108: 0.0686 | E108: 0.81 | F108: 0.7974 | G108: 0.8242 | H108: 0.63 | I108: 0.94 | J108: 8.5
B109: PG | C109: 0.9238 | D109: 0.0493 | E109: 0.93 | F109: 0.9141 | G109: 0.9335 | H109: 0.76 | I109: 1.03 | J109: 5.3
B110: PRA | C110: 0.5447 | D110: 0.079 | E110: 0.55 | F110: 0.5292 | G110: 0.5602 | H110: 0.37 | I110: 0.72 | J110: 14.5
B111: PRB | C111: 0.8827 | D111: 0.037 | E111: 0.89 | F111: 0.8754 | G111: 0.89 | H111: 0.77 | I111: 0.96 | J111: 4.2
B112: PRD | C112: 0.9309 | D112: 0.0392 | E112: 0.93 | F112: 0.9232 | G112: 0.9386 | H112: 0.83 | I112: 1.03 | J112: 4.2
B115: 2. TESTE DE LEVENE
B116: Estatística F | C116: p-valor | D116: Resultado
B117: 21.5933 | C117: < 0,001 | D117: Não Homogêneas
B120: 3. ANOVA DE WELCH
B121: F | C121: gl entre | D121: gl dentro | E121: p-valor | F121: Resultado
B122: 504.3589 | C122: 5 | D122: 8 | E122: < 0,001 | F122: Significativa
B125: 4. TESTE POST-HOC - Games-Howell
B126: Grupo 1 | C126: Grupo 2 | D126: Diferença | E126: Erro Padrão | F126: IC 95% Inferior | G126: IC 95% Superior | H126: p-valor | I126: Significativo
B127: PR | C127: PBA | D127: -0.0191 | E127: 0.0077 | F127: -0.0342 | G127: -0.004 | H127: 0.0138 | I127: SIM
B128: PR | C128: PG | D128: -0.1321 | E128: 0.006 | F128: -0.1439 | G128: -0.1203 | H128: < 0,001 | I128: SIM
B129: PR | C129: PRA | D129: 0.247 | E129: 0.0086 | F129: 0.23 | G129: 0.264 | H129: < 0,001 | I129: SIM
B130: PR | C130: PRB | D130: -0.091 | E130: 0.005 | F130: -0.1009 | G130: -0.0811 | H130: < 0,001 | I130: SIM
B131: PR | C131: PRD | D131: -0.1392 | E131: 0.0052 | F131: -0.1495 | G131: -0.1289 | H131: < 0,001 | I131: SIM
B132: PBA | C132: PG | D132: -0.113 | E132: 0.0084 | F132: -0.1297 | G132: -0.0963 | H132: < 0,001 | I132: SIM
B133: PBA | C133: PRA | D133: 0.2661 | E133: 0.0105 | F133: 0.2455 | G133: 0.2867 | H133: < 0,001 | I133: SIM
B134: PBA | C134: PRB | D134: -0.0719 | E134: 0.0078 | F134: -0.0873 | G134: -0.0565 | H134: < 0,001 | I134: SIM
B135: PBA | C135: PRD | D135: -0.1201 | E135: 0.0079 | F135: -0.1357 | G135: -0.1045 | H135: < 0,001 | I135: SIM
...

Sheet Tds_Esp_Distância
B1: Distância em 100 Episódios - Robôs Especialistas
B2: PR | C2: PBA | D2: PG | E2: PRA | F2: PRB | G2: PRD
B3: 9.02 | C3: 6.12 | D3: 9.01 | E3: 1.52 | F3: 7.57 | G3: 9.02
B4: 7.82 | C4: 5.99 | D4: 9.02 | E4: 1.05 | F4: 9.02 | G4: 9.02
B5: 9.01 | C5: 4.23 | D5: 9 | E5: 7.36 | F5: 9.05 | G5: 9
B6: 7.92 | C6: 9.03 | D6: 9 | E6: 8.31 | F6: 9.02 | G6: 9.01
B7: 9.02 | C7: 9 | D7: 9.02 | E7: 1.04 | F7: 7.63 | G7: 4.9
B8: 8.8 | C8: 9.01 | D8: 9.01 | E8: 7.8 | F8: 9.02 | G8: 9
B9: 6.62 | C9: 1.4 | D9: 9.01 | E9: 1.13 | F9: 6.16 | G9: 8.05
B10: 8.07 | C10: 5.42 | D10: 9 | E10: 9 | F10: 5.94 | G10: 9.01
B11: 5.71 | C11: 6.3 | D11: 9.02 | E11: 6.58 | F11: 8.11 | G11: 9.01
B12: 5.91 | C12: 4.69 | D12: 0.55 | E12: 9.01 | F12: 9.01 | G12: 9.02
B13: 9.03 | C13: 5.6 | D13: 9.01 | E13: 1.35 | F13: 9.03 | G13: 8.76
B14: 9.01 | C14: 6.77 | D14: 9.01 | E14: 1 | F14: 9.05 | G14: 9.02
... B102: 5.35 | C102: 9.03 | D102: 8.59 | E102: 9 | F102: 9.01 | G102: 9.02
B105: 1. ESTATÍSTICAS DESCRITIVAS
B106: Variável | C106: Média | D106: DP | E106: Mediana | F106: IC 95% Inferior | G106: IC 95% Superior | H106: Mínimo | I106: Máximo | J106: CV (%)
B107: PR | C107: 7.6553 | D107: 1.9539 | E107: 9 | F107: 7.2723 | G107: 8.0383 | H107: 1.03 | I107: 9.03 | J107: 25.5
B108: PBA | C108: 5.4985 | D108: 3.1773 | E108: 5.985 | F108: 4.8758 | G108: 6.1212 | H108: -0.3 | I108: 9.04 | J108: 57.8
B109: PG | C109: 8.5516 | D109: 1.5626 | E109: 9.01 | F109: 8.2453 | G109: 8.8579 | H109: 0.29 | I109: 9.04 | J109: 18.3
B110: PRA | C110: 3.7686 | D110: 3.2612 | E110: 1.835 | F110: 3.1294 | G110: 4.4078 | H110: -0.21 | I110: 9.04 | J110: 86.5
B111: PRB | C111: 8.5111 | D111: 1.3209 | E111: 9.01 | F111: 8.2522 | G111: 8.77 | H111: 1.94 | I111: 9.05 | J111: 15.5
B112: PRD | C112: 8.7531 | D112: 0.8814 | E112: 9.01 | F112: 8.5804 | G112: 8.9258 | H112: 4.42 | I112: 9.05 | J112: 10.1
B115: 2. TESTE DE LEVENE
B116: Estatística F | C116: p-valor | D116: Resultado
B117: 34.3282 | C117: < 0,001 | D117: Não Homogêneas
B120: 3. ANOVA DE WELCH
B121: F | C121: gl entre | D121: gl dentro | E121: p-valor | F121: Resultado
B122: 62.0093 | C122: 5 | D122: 8 | E122: < 0,001 | F122: Significativa
B125: 4. TESTE POST-HOC - Games-Howell
B126: Grupo 1 | C126: Grupo 2 | D126: Diferença | E126: Erro Padrão | F126: IC 95% Inferior | G126: IC 95% Superior | H126: p-valor | I126: Significativo
B127: PR | C127: PBA | D127: 2.1568 | E127: 0.373 | F127: 1.4203 | G127: 2.8933 | H127: < 0,001 | I127: SIM
B128: PR | C128: PG | D128: -0.8963 | E128: 0.2502 | F128: -1.3898 | G128: -0.4028 | H128: < 0,001 | I128: SIM
B129: PR | C129: PRA | D129: 3.8867 | E129: 0.3802 | F129: 3.136 | G129: 4.6374 | H129: < 0,001 | I129: SIM
B130: PR | C130: PRB | D130: -0.8558 | E130: 0.2359 | F130: -1.3213 | G130: -0.3903 | H130: < 0,001 | I130: SIM
B131: PR | C131: PRD | D131: -1.0978 | E131: 0.2144 | F131: -1.5216 | G131: -0.674 | H131: < 0,001 | I131: SIM
B132: PBA | C132: PG | D132: -3.0531 | E132: 0.3541 | F132: -3.7529 | G132: -2.3533 | H132: < 0,001 | I132: SIM
B133: PBA | C133: PRA | D133: 1.7299 | E133: 0.4553 | F133: 0.832 | G133: 2.6278 | H133: < 0,001 | I133: SIM
B134: PBA | C134: PRB | D134: -3.0126 | E134: 0.3441 | F134: -3.6932 | G134: -2.332 | H134: < 0,001 | I134: SIM
B135: PBA | C135: PRD | D135: -3.2546 | E135: 0.3297 | F135: -3.9078 | G135: -2.6014 | H135: < 0,001 | I135: SIM
...

Sheet Tds_Esp_Velocidade
B1: Velocidade Média em 100 Episódios - Robôs Especialistas
B2: PR | C2: PBA | D2: PG | E2: PRA | F2: PRB | G2: PRD
B3: 0.79 | C3: 0.67 | D3: 0.9 | E3: 0.22 | F3: 0.78 | G3: 0.93
B4: 0.74 | C4: 0.83 | D4: 0.88 | E4: 0.06 | F4: 0.87 | G4: 0.92
B5: 0.79 | C5: 0.7 | D5: 0.86 | E5: 0.45 | F5: 0.85 | G5: 0.89
B6: 0.77 | C6: 0.72 | D6: 0.96 | E6: 0.47 | F6: 0.94 | G6: 0.92
B7: 0.76 | C7: 0.83 | D7: 0.96 | E7: 0.1 | F7: 0.88 | G7: 0.77
B8: 0.76 | C8: 0.88 | D8: 0.91 | E8: 0.45 | F8: 0.91 | G8: 0.88
B9: 0.68 | C9: 0.46 | D9: 0.98 | E9: 0.09 | F9: 0.88 | G9: 0.89
B10: 0.78 | C10: 0.73 | D10: 0.87 | E10: 0.6 | F10: 0.84 | G10: 0.89
B11: 0.74 | C11: 0.74 | D11: 0.92 | E11: 0.5 | F11: 0.77 | G11: 0.98
B12: 0.7 | C12: 0.72 | D12: 0.34 | E12: 0.52 | F12: 0.88 | G12: 0.92
B13: 0.79 | C13: 0.67 | D13: 0.98 | E13: 0.12 | F13: 0.82 | G13: 0.97
B14: 0.78 | C14: 0.79 | D14: 0.93 | E14: 0.38 | F14: 0.84 | G14: 1.03
... B102: 0.83 | C102: 0.83 | D102: 0.84 | E102: 0.37 | F102: 0.81 | G102: 0.9
B105: 1. ESTATÍSTICAS DESCRITIVAS
B106: Variável | C106: Média | D106: DP | E106: Mediana | F106: IC 95% Inferior | G106: IC 95% Superior | H106: Mínimo | I106: Máximo | J106: CV (%)
B107: PR | C107: 0.7623 | D107: 0.0719 | E107: 0.78 | F107: 0.7482 | G107: 0.7764 | H107: 0.37 | I107: 0.88 | J107: 9.4
B108: PBA | C108: 0.6083 | D108: 0.2881 | E108: 0.72 | F108: 0.5518 | G108: 0.6648 | H108: -0.09 | I108: 0.94 | J108: 47.4
B109: PG | C109: 0.8824 | D109: 0.1272 | E109: 0.92 | F109: 0.8575 | G109: 0.9073 | H109: 0.12 | I109: 1.03 | J109: 14.4
B110: PRA | C110: 0.2983 | D110: 0.2112 | E110: 0.3 | F110: 0.2569 | G110: 0.3397 | H110: -0.02 | I110: 0.74 | J110: 70.8
B111: PRB | C111: 0.8601 | D111: 0.0759 | E111: 0.87 | F111: 0.8452 | G111: 0.875 | H111: 0.38 | I111: 0.96 | J111: 8.8
B112: PRD | C112: 0.9219 | D112: 0.052 | E112: 0.92 | F112: 0.9117 | G112: 0.9321 | H112: 0.74 | I112: 1.03 | J112: 5.6
B115: 2. TESTE DE LEVENE
B116: Estatística F | C116: p-valor | D116: Resultado
B117: 35.1451 | C117: < 0,001 | D117: Não Homogêneas
B120: 3. ANOVA DE WELCH
B121: F | C121: gl entre | D121: gl dentro | E121: p-valor | F121: Resultado
B122: 217.9904 | C122: 5 | D122: 8 | E122: < 0,001 | F122: Significativa
B125: 4. TESTE POST-HOC - Games-Howell
B126: Grupo 1 | C126: Grupo 2 | D126: Diferença | E126: Erro Padrão | F126: IC 95% Inferior | G126: IC 95% Superior | H126: p-valor | I126: Significativo
B127: PR | C127: PBA | D127: 0.154 | E127: 0.0297 | F127: 0.0952 | G127: 0.2128 | H127: < 0,001 | I127: SIM
B128: PR | C128: PG | D128: -0.1201 | E128: 0.0146 | F128: -0.149 | G128: -0.0912 | H128: < 0,001 | I128: SIM
B129: PR | C129: PRA | D129: 0.464 | E129: 0.0223 | F129: 0.4198 | G129: 0.5082 | H129: < 0,001 | I129: SIM
B130: PR | C130: PRB | D130: -0.0978 | E130: 0.0104 | F130: -0.1184 | G130: -0.0772 | H130: < 0,001 | I130: SIM
B131: PR | C131: PRD | D131: -0.1596 | E131: 0.0089 | F131: -0.1771 | G131: -0.1421 | H131: < 0,001 | I131: SIM
B132: PBA | C132: PG | D132: -0.2741 | E132: 0.0315 | F132: -0.3364 | G132: -0.2118 | H132: < 0,001 | I132: SIM
B133: PBA | C133: PRA | D133: 0.31 | E133: 0.0357 | F133: 0.2395 | G133: 0.3805 | H133: < 0,001 | I133: SIM
B134: PBA | C134: PRB | D134: -0.2518 | E134: 0.0298 | F134: -0.3108 | G134: -0.1928 | H134: < 0,001 | I134: SIM
B135: PBA | C135: PRD | D135: -0.3136 | E135: 0.0293 | F135: -0.3717 | G135: -0.2555 | H135: < 0,001 | I135: SIM
...

Sheet Suc_CC_Tempo
B1: Tempo dos Episódios / Completos de 9 m - Generalista CC
B2: PR | C2: PBA | D2: PG | E2: PRA | F2: PRB | G2: PRD
B3: 12.07 | C3: 12.07 | D3: 10.93 | E3: 14.83 | F3: 11.37 | G3: 10.2
B4: 12.17 | C4: 11.63 | D4: 10.07 | E4: 15.67 | F4: 12.53 | G4: 10.77
B5: 10.87 | C5: 12.77 | D5: 10.77 | E5: 14.57 | F5: 12.23 | G5: 9.4
B6: 11.37 | C6: 11.5 | D6: 11.57 | E6: 17.07 | F6: 11.3 | G6: 9.43
B7: 11.13 | C7: 11.1 | D7: 10.23 | E7: 17.57 | F7: 11.5 | G7: 9.4
B8: 11 | C8: 11.57 | D8: 10.93 | E8: 18.23 | F8: 13.3 | G8: 9.27
B9: 11.8 | C9: 11.13 | D9: 10.73 | E9: 14.87 | F9: 11.5 | G9: 10.43
B10: 12.4 | C10: 11.83 | D10: 10.33 | E10: 16.77 | F10: 13.37 | G10: 10.13
B11: 11.27 | C11: 12.13 | D11: 10.77 | E11: 14.67 | F11: 11.67 | G11: 10.53
B12: 12.07 | C12: 12.2 | D12: 10.17 | E12: 17.47 | F12: 12.2 | G12: 10.8
B13: 12.53 | C13: 12.3 | D13: 10.07 | E13: 14.83 | F13: 12.17 | G13: 9.77
B14: 11.33 | C14: 12.4 | D14: 10.73 | E14: 15.1 | F14: 11.57 | G14: 9.53
... B102: 11.33 | C102: 11.2 | D102: 10.73 | E102: 16 | F102: 13.6 | G102: 9.77
B105: 1. ESTATÍSTICAS DESCRITIVAS
B106: Variável | C106: Média | D106: DP | E106: Mediana | F106: IC 95% Inferior | G106: IC 95% Superior | H106: Mínimo | I106: Máximo | J106: CV (%)
B107: PR | C107: 11.5672 | D107: 0.5929 | E107: 11.5 | F107: 11.451 | G107: 11.6834 | H107: 10.4 | I107: 13 | J107: 5.1
B108: PBA | C108: 11.6628 | D108: 0.5607 | E108: 11.6 | F108: 11.5529 | G108: 11.7727 | H108: 10.63 | I108: 13.33 | J108: 4.8
B109: PG | C109: 10.8223 | D109: 0.5207 | E109: 10.75 | F109: 10.7202 | G109: 10.9244 | H109: 9.8 | I109: 12.7 | J109: 4.8
B110: PRA | C110: 16.0655 | D110: 0.9928 | E110: 15.985 | F110: 15.8709 | G110: 16.2601 | H110: 14.13 | I110: 18.37 | J110: 6.2
B111: PRB | C111: 11.9652 | D111: 0.7913 | E111: 11.83 | F111: 11.8101 | G111: 12.1203 | H111: 10.53 | I111: 15.23 | J111: 6.6
B112: PRD | C112: 10.2297 | D112: 0.5594 | E112: 10.2 | F112: 10.1201 | G112: 10.3393 | H112: 9.27 | I112: 12.23 | J112: 5.5
B115: 2. TESTE DE LEVENE
B116: Estatística F | C116: p-valor | D116: Resultado
B117: 13.033 | C117: < 0,001 | D117: Não Homogêneas
B120: 3. ANOVA DE WELCH
B121: F | C121: gl entre | D121: gl dentro | E121: p-valor | F121: Resultado
B122: 563.1099 | C122: 5 | D122: 8 | E122: < 0,001 | F122: Significativa
B125: 4. TESTE POST-HOC - Games-Howell
B126: Grupo 1 | C126: Grupo 2 | D126: Diferença | E126: Erro Padrão | F126: IC 95% Inferior | G126: IC 95% Superior | H126: p-valor | I126: Significativo
B127: PR | C127: PBA | D127: -0.0956 | E127: 0.0816 | F127: -0.2565 | G127: 0.0653 | H127: 0.2428 | I127: NÃO
B128: PR | C128: PG | D128: 0.7449 | E128: 0.0789 | F128: 0.5893 | G128: 0.9005 | H128: < 0,001 | I128: SIM
B129: PR | C129: PRA | D129: -4.4983 | E129: 0.1156 | F129: -4.7266 | G129: -4.27 | H129: < 0,001 | I129: SIM
B130: PR | C130: PRB | D130: -0.398 | E130: 0.0989 | F130: -0.5931 | G130: -0.2029 | H130: < 0,001 | I130: SIM
B131: PR | C131: PRD | D131: 1.3375 | E131: 0.0815 | F131: 1.1768 | G131: 1.4982 | H131: < 0,001 | I131: SIM
B132: PBA | C132: PG | D132: 0.8405 | E132: 0.0765 | F132: 0.6896 | G132: 0.9914 | H132: < 0,001 | I132: SIM
B133: PBA | C133: PRA | D133: -4.4027 | E133: 0.114 | F133: -4.6279 | G133: -4.1775 | H133: < 0,001 | I133: SIM
B134: PBA | C134: PRB | D134: -0.3024 | E134: 0.097 | F134: -0.4938 | G134: -0.111 | H134: 0.002 | I134: SIM
B135: PBA | C135: PRD | D135: 1.4331 | E135: 0.0792 | F135: 1.2769 | G135: 1.5893 | H135: < 0,001 | I135: SIM
...

Sheet Suc_CC_Velocidade
B1: Velocidade Média / Completos 9 m - Generalista CC
B2: PR | C2: PBA | D2: PG | E2: PRA | F2: PRB | G2: PRD
B3: 0.75 | C3: 0.75 | D3: 0.82 | E3: 0.61 | F3: 0.79 | G3: 0.88
B4: 0.74 | C4: 0.78 | D4: 0.9 | E4: 0.58 | F4: 0.72 | G4: 0.84
B5: 0.83 | C5: 0.71 | D5: 0.84 | E5: 0.62 | F5: 0.74 | G5: 0.96
B6: 0.79 | C6: 0.78 | D6: 0.78 | E6: 0.53 | F6: 0.8 | G6: 0.96
B7: 0.81 | C7: 0.81 | D7: 0.88 | E7: 0.51 | F7: 0.79 | G7: 0.96
B8: 0.82 | C8: 0.78 | D8: 0.82 | E8: 0.49 | F8: 0.68 | G8: 0.97
B9: 0.76 | C9: 0.81 | D9: 0.84 | E9: 0.61 | F9: 0.78 | G9: 0.86
B10: 0.73 | C10: 0.76 | D10: 0.87 | E10: 0.54 | F10: 0.67 | G10: 0.89
B11: 0.8 | C11: 0.74 | D11: 0.84 | E11: 0.61 | F11: 0.77 | G11: 0.86
B12: 0.75 | C12: 0.74 | D12: 0.89 | E12: 0.52 | F12: 0.74 | G12: 0.83
B13: 0.72 | C13: 0.73 | D13: 0.9 | E13: 0.61 | F13: 0.74 | G13: 0.92
B14: 0.8 | C14: 0.73 | D14: 0.84 | E14: 0.6 | F14: 0.78 | G14: 0.95
... B102: 0.79 | C102: 0.8 | D102: 0.84 | E102: 0.56 | F102: 0.66 | G102: 0.92
B105: 1. ESTATÍSTICAS DESCRITIVAS
B106: Variável | C106: Média | D106: DP | E106: Mediana | F106: IC 95% Inferior | G106: IC 95% Superior | H106: Mínimo | I106: Máximo | J106: CV (%)
B107: PR | C107: 0.7812 | D107: 0.0404 | E107: 0.78 | F107: 0.7733 | G107: 0.7891 | H107: 0.69 | I107: 0.87 | J107: 5.2
B108: PBA | C108: 0.7743 | D108: 0.0357 | E108: 0.78 | F108: 0.7673 | G108: 0.7813 | H108: 0.68 | I108: 0.85 | J108: 4.6
B109: PG | C109: 0.8348 | D109: 0.0393 | E109: 0.84 | F109: 0.8271 | G109: 0.8425 | H109: 0.71 | I109: 0.92 | J109: 4.7
B110: PRA | C110: 0.5635 | D110: 0.035 | E110: 0.56 | F110: 0.5566 | G110: 0.5704 | H110: 0.49 | I110: 0.64 | J110: 6.2
B111: PRB | C111: 0.7566 | D111: 0.0468 | E111: 0.76 | F111: 0.7474 | G111: 0.7658 | H111: 0.59 | I111: 0.86 | J111: 6.2
B112: PRD | C112: 0.8834 | D112: 0.0474 | E112: 0.88 | F112: 0.8741 | G112: 0.8927 | H112: 0.74 | I112: 0.97 | J112: 5.4
B115: 2. TESTE DE LEVENE
B116: Estatística F | C116: p-valor | D116: Resultado
B117: 2.7277 | C117: 0.019 | D117: Não Homogêneas
B120: 3. ANOVA DE WELCH
B121: F | C121: gl entre | D121: gl dentro | E121: p-valor | F121: Resultado
B122: 831.6822 | C122: 5 | D122: 8 | E122: < 0,001 | F122: Significativa
B125: 4. TESTE POST-HOC - Games-Howell
B126: Grupo 1 | C126: Grupo 2 | D126: Diferença | E126: Erro Padrão | F126: IC 95% Inferior | G126: IC 95% Superior | H126: p-valor | I126: Significativo
B127: PR | C127: PBA | D127: 0.0069 | E127: 0.0054 | F127: -0.0037 | G127: 0.0175 | H127: 0.2022 | I127: NÃO
B128: PR | C128: PG | D128: -0.0536 | E128: 0.0056 | F128: -0.0647 | G128: -0.0425 | H128: < 0,001 | I128: SIM
B129: PR | C129: PRA | D129: 0.2177 | E129: 0.0053 | F129: 0.2072 | G129: 0.2282 | H129: < 0,001 | I129: SIM
B130: PR | C130: PRB | D130: 0.0246 | E130: 0.0062 | F130: 0.0124 | G130: 0.0368 | H130: < 0,001 | I130: SIM
B131: PR | C131: PRD | D131: -0.1022 | E131: 0.0062 | F131: -0.1145 | G131: -0.0899 | H131: < 0,001 | I131: SIM
B132: PBA | C132: PG | D132: -0.0605 | E132: 0.0053 | F132: -0.071 | G132: -0.05 | H132: < 0,001 | I132: SIM
B133: PBA | C133: PRA | D133: 0.2108 | E133: 0.005 | F133: 0.2009 | G133: 0.2207 | H133: < 0,001 | I133: SIM
B134: PBA | C134: PRB | D134: 0.0177 | E134: 0.0059 | F134: 0.0061 | G134: 0.0293 | H134: 0.003 | I134: SIM
B135: PBA | C135: PRD | D135: -0.1091 | E135: 0.0059 | F135: -0.1208 | G135: -0.0974 | H135: < 0,001 | I135: SIM
...

Sheet Tds_CC_Distância
B1: Distância em 100 Episódios - Generalista CC
B2: PR | C2: PBA | D2: PG | E2: PRA | F2: PRB | G2: PRD
B3: 9.02 | C3: 9 | D3: 6.07 | E3: 9.02 | F3: 4.44 | G3: 9.02
B4: 9.02 | C4: 9.02 | D4: 9.01 | E4: 6.87 | F4: 9.02 | G4: 9.02
B5: 9.02 | C5: 9.01 | D5: 8.87 | E5: 9.03 | F5: 9.02 | G5: 9.02
B6: 9.01 | C6: 2.86 | D6: 7.05 | E6: 9.01 | F6: 4.61 | G6: 9.02
B7: 9.02 | C7: 9.01 | D7: 5.63 | E7: 9.01 | F7: 3.9 | G7: 9.02
B8: 6.24 | C8: 9.01 | D8: 7.07 | E8: 9 | F8: 4.09 | G8: 9.03
B9: 9.01 | C9: 9.02 | D9: 9.03 | E9: 2.79 | F9: 2.07 | G9: 9.02
B10: 9.01 | C10: 5.53 | D10: 5.66 | E10: 3.56 | F10: 9.01 | G10: 1.45
B11: 9 | C11: 9 | D11: 2.23 | E11: 9.01 | F11: 8.59 | G11: 9.01
B12: 4.81 | C12: 9 | D12: 7.38 | E12: 8.23 | F12: 4.3 | G12: 9.01
B13: 9.02 | C13: 9.02 | D13: 3.6 | E13: 9.03 | F13: 9.01 | G13: 9.01
B14: 9.02 | C14: 9 | D14: 9.02 | E14: 9.03 | F14: 9.03 | G14: 9.02
... B102: 9.01 | C102: 9 | D102: 8.75 | E102: 2.53 | F102: 9 | G102: 9.01
B105: 1. ESTATÍSTICAS DESCRITIVAS
B106: Variável | C106: Média | D106: DP | E106: Mediana | F106: IC 95% Inferior | G106: IC 95% Superior | H106: Mínimo | I106: Máximo | J106: CV (%)
B107: PR | C107: 8.5574 | D107: 1.4252 | E107: 9.01 | F107: 8.2781 | G107: 8.8367 | H107: 1.81 | I107: 9.03 | J107: 16.7
B108: PBA | C108: 8.4592 | D108: 1.5251 | E108: 9.01 | F108: 8.1603 | G108: 8.7581 | H108: 1.48 | I108: 9.03 | J108: 18
B109: PG | C109: 7.1524 | D109: 1.877 | E109: 7.695 | F109: 6.7845 | G109: 7.5203 | H109: 0.81 | I109: 9.03 | J109: 26.2
B110: PRA | C110: 7.5673 | D110: 2.2529 | E110: 9 | F110: 7.1257 | G110: 8.0089 | H110: 1.58 | I110: 9.04 | J110: 29.8
B111: PRB | C111: 7.5736 | D111: 2.0697 | E111: 9 | F111: 7.1679 | G111: 7.9793 | H111: 2.07 | I111: 9.03 | J111: 27.3
B112: PRD | C112: 8.5144 | D112: 1.4778 | E112: 9.01 | F112: 8.2247 | G112: 8.8041 | H112: 1.45 | I112: 9.03 | J112: 17.4
B115: 2. TESTE DE LEVENE
B116: Estatística F | C116: p-valor | D116: Resultado
B117: 9.6591 | C117: < 0,001 | D117: Não Homogêneas
B120: 3. ANOVA DE WELCH
B121: F | C121: gl entre | D121: gl dentro | E121: p-valor | F121: Resultado
B122: 12.0846 | C122: 5 | D122: 8 | E122: 0.002 | F122: Significativa
B125: 4. TESTE POST-HOC - Games-Howell
B126: Grupo 1 | C126: Grupo 2 | D126: Diferença | E126: Erro Padrão | F126: IC 95% Inferior | G126: IC 95% Superior | H126: p-valor | I126: Significativo
B127: PR | C127: PBA | D127: 0.0982 | E127: 0.2087 | F127: -0.3135 | G127: 0.5099 | H127: 0.6386 | I127: NÃO
B128: PR | C128: PG | D128: 1.405 | E128: 0.2357 | F128: 0.94 | G128: 1.87 | H128: < 0,001 | I128: SIM
B129: PR | C129: PRA | D129: 0.9901 | E129: 0.2666 | F129: 0.4638 | G129: 1.5164 | H129: < 0,001 | I129: SIM
B130: PR | C130: PRB | D130: 0.9838 | E130: 0.2513 | F130: 0.4879 | G130: 1.4797 | H130: < 0,001 | I130: SIM
B131: PR | C131: PRD | D131: 0.043 | E131: 0.2053 | F131: -0.3619 | G131: 0.4479 | H131: 0.8343 | I131: NÃO
B132: PBA | C132: PG | D132: 1.3068 | E132: 0.2418 | F132: 0.8297 | G132: 1.7839 | H132: < 0,001 | I132: SIM
B133: PBA | C133: PRA | D133: 0.8919 | E133: 0.2721 | F133: 0.3549 | G133: 1.4289 | H133: 0.001 | I133: SIM
B134: PBA | C134: PRB | D134: 0.8856 | E134: 0.2571 | F134: 0.3783 | G134: 1.3929 | H134: < 0,001 | I134: SIM
B135: PBA | C135: PRD | D135: -0.0552 | E135: 0.2124 | F135: -0.474 | G135: 0.3636 | H135: 0.7952 | I135: NÃO
...

Sheet Tds_CC_Velocidade
B1: Velocidade Média em 100 Episódios - Generalista CC
B2: PR | C2: PBA | D2: PG | E2: PRA | F2: PRB | G2: PRD
B3: 0.75 | C3: 0.75 | D3: 0.8 | E3: 0.61 | F3: 0.57 | G3: 0.88
B4: 0.74 | C4: 0.78 | D4: 0.82 | E4: 0.52 | F4: 0.79 | G4: 0.84
B5: 0.83 | C5: 0.71 | D5: 0.79 | E5: 0.58 | F5: 0.72 | G5: 0.96
B6: 0.79 | C6: 0.52 | D6: 0.88 | E6: 0.62 | F6: 0.6 | G6: 0.96
B7: 0.81 | C7: 0.78 | D7: 0.72 | E7: 0.53 | F7: 0.71 | G7: 0.96
B8: 0.7 | C8: 0.81 | D8: 0.67 | E8: 0.51 | F8: 0.75 | G8: 0.97
B9: 0.82 | C9: 0.78 | D9: 0.9 | E9: 0.44 | F9: 0.51 | G9: 0.86
B10: 0.76 | C10: 0.71 | D10: 0.69 | E10: 0.37 | F10: 0.74 | G10: 0.66
B11: 0.73 | C11: 0.81 | D11: 0.5 | E11: 0.49 | F11: 0.78 | G11: 0.89
B12: 0.76 | C12: 0.76 | D12: 0.79 | E12: 0.54 | F12: 0.56 | G12: 0.86
B13: 0.8 | C13: 0.74 | D13: 0.58 | E13: 0.61 | F13: 0.8 | G13: 0.83
B14: 0.75 | C14: 0.74 | D14: 0.84 | E14: 0.54 | F14: 0.79 | G14: 0.92
... B102: 0.74 | C102: 0.84 | D102: 0.84 | E102: 0.31 | F102: 0.81 | G102: 0.94
B105: 1. ESTATÍSTICAS DESCRITIVAS
B106: Variável | C106: Média | D106: DP | E106: Mediana | F106: IC 95% Inferior | G106: IC 95% Superior | H106: Mínimo | I106: Máximo | J106: CV (%)
B107: PR | C107: 0.7712 | D107: 0.0509 | E107: 0.77 | F107: 0.7612 | G107: 0.7812 | H107: 0.59 | I107: 0.87 | J107: 6.6
B108: PBA | C108: 0.7561 | D108: 0.0885 | E108: 0.77 | F108: 0.7388 | G108: 0.7734 | H108: 0.1 | I108: 0.85 | J108: 11.7
B109: PG | C109: 0.7754 | D109: 0.1016 | E109: 0.795 | F109: 0.7555 | G109: 0.7953 | H109: 0.22 | I109: 0.9 | J109: 13.1
B110: PRA | C110: 0.5295 | D110: 0.0809 | E110: 0.54 | F110: 0.5136 | G110: 0.5454 | H110: 0.07 | I110: 0.64 | J110: 15.3
B111: PRB | C111: 0.7268 | D111: 0.1033 | E111: 0.75 | F111: 0.7066 | G111: 0.747 | H111: 0.13 | I111: 0.86 | J111: 14.2
B112: PRD | C112: 0.8726 | D112: 0.0662 | E112: 0.88 | F112: 0.8596 | G112: 0.8856 | H112: 0.6 | I112: 0.97 | J112: 7.6
B115: 2. TESTE DE LEVENE
B116: Estatística F | C116: p-valor | D116: Resultado
B117: 2.6752 | C117: 0.0211 | D117: Não Homogêneas
B120: 3. ANOVA DE WELCH
B121: F | C121: gl entre | D121: gl dentro | E121: p-valor | F121: Resultado
B122: 220.4003 | C122: 5 | D122: 8 | E122: < 0,001 | F122: Significativa
B125: 4. TESTE POST-HOC - Games-Howell
B126: Grupo 1 | C126: Grupo 2 | D126: Diferença | E126: Erro Padrão | F126: IC 95% Inferior | G126: IC 95% Superior | H126: p-valor | I126: Significativo
B127: PR | C127: PBA | D127: 0.0151 | E127: 0.0102 | F127: -0.0051 | G127: 0.0353 | H127: 0.1411 | I127: NÃO
B128: PR | C128: PG | D128: -0.0042 | E128: 0.0114 | F128: -0.0267 | G128: 0.0183 | H128: 0.7124 | I128: NÃO
B129: PR | C129: PRA | D129: 0.2417 | E129: 0.0096 | F129: 0.2228 | G129: 0.2606 | H129: < 0,001 | I129: SIM
B130: PR | C130: PRB | D130: 0.0444 | E130: 0.0115 | F130: 0.0216 | G130: 0.0672 | H130: < 0,001 | I130: SIM
B131: PR | C131: PRD | D131: -0.1014 | E131: 0.0084 | F131: -0.1179 | G131: -0.0849 | H131: < 0,001 | I131: SIM
B132: PBA | C132: PG | D132: -0.0193 | E132: 0.0135 | F132: -0.0459 | G132: 0.0073 | H132: 0.1537 | I132: NÃO
B133: PBA | C133: PRA | D133: 0.2266 | E133: 0.012 | F133: 0.2029 | G133: 0.2503 | H133: < 0,001 | I133: SIM
B134: PBA | C134: PRB | D134: 0.0293 | E134: 0.0136 | F134: 0.0025 | G134: 0.0561 | H134: 0.0325 | I134: SIM
B135: PBA | C135: PRD | D135: -0.1165 | E135: 0.0111 | F135: -0.1383 | G135: -0.0947 | H135: < 0,001 | I135: SIM
...
